"""API 異常處理測試

此模組測試 API 異常處理功能，包括自定義異常類別、異常處理器、
錯誤追蹤器等。
"""

import pytest
from unittest.mock import Mock, patch, MagicMock
import sys
from datetime import datetime

# 模擬相依性模組
sys.modules["fastapi"] = MagicMock()
sys.modules["fastapi.exceptions"] = MagicMock()
sys.modules["fastapi.responses"] = MagicMock()
sys.modules["pydantic"] = MagicMock()
sys.modules["src.api.models.responses"] = MagicMock()


class TestAPIExceptions:
    """API 異常處理測試類別"""

    def setup_method(self):
        """測試前置設定"""
        self.test_timestamp = datetime.now()

    def test_api_exception_base_class(self):
        """測試 API 異常基類"""

        # 模擬 APIException 基類
        class MockAPIException(Exception):
            def __init__(
                self, message: str, error_code: int = 500, details: dict = None
            ):
                self.message = message
                self.error_code = error_code
                self.details = details or {}
                super().__init__(self.message)

        # 測試基本功能
        exc = MockAPIException("測試錯誤", 400, {"field": "test"})
        assert exc.message == "測試錯誤"
        assert exc.error_code == 400
        assert exc.details == {"field": "test"}
        assert str(exc) == "測試錯誤"

    def test_authentication_error(self):
        """測試認證錯誤"""

        # 模擬 AuthenticationError
        class MockAuthenticationError(Exception):
            def __init__(self, message: str = "認證失敗", details: dict = None):
                self.message = message
                self.error_code = 401
                self.details = details or {}

        exc = MockAuthenticationError()
        assert exc.message == "認證失敗"
        assert exc.error_code == 401

        # 測試自定義訊息
        custom_exc = MockAuthenticationError("Token 已過期")
        assert custom_exc.message == "Token 已過期"
        assert custom_exc.error_code == 401

    def test_authorization_error(self):
        """測試授權錯誤"""

        # 模擬 AuthorizationError
        class MockAuthorizationError(Exception):
            def __init__(self, message: str = "權限不足", details: dict = None):
                self.message = message
                self.error_code = 403
                self.details = details or {}

        exc = MockAuthorizationError()
        assert exc.message == "權限不足"
        assert exc.error_code == 403

    def test_validation_error(self):
        """測試驗證錯誤"""

        # 模擬 DataValidationError
        class MockDataValidationError(Exception):
            def __init__(self, message: str = "資料驗證失敗", details: dict = None):
                self.message = message
                self.error_code = 422
                self.details = details or {}

        exc = MockDataValidationError()
        assert exc.message == "資料驗證失敗"
        assert exc.error_code == 422

    def test_not_found_error(self):
        """測試資源不存在錯誤"""

        # 模擬 NotFoundError
        class MockNotFoundError(Exception):
            def __init__(self, message: str = "資源不存在", details: dict = None):
                self.message = message
                self.error_code = 404
                self.details = details or {}

        exc = MockNotFoundError("用戶不存在")
        assert exc.message == "用戶不存在"
        assert exc.error_code == 404

    def test_conflict_error(self):
        """測試衝突錯誤"""

        # 模擬 ConflictError
        class MockConflictError(Exception):
            def __init__(self, message: str = "資源衝突", details: dict = None):
                self.message = message
                self.error_code = 409
                self.details = details or {}

        exc = MockConflictError("用戶名已存在")
        assert exc.message == "用戶名已存在"
        assert exc.error_code == 409

    def test_rate_limit_error(self):
        """測試速率限制錯誤"""

        # 模擬 RateLimitError
        class MockRateLimitError(Exception):
            def __init__(self, message: str = "請求過於頻繁", details: dict = None):
                self.message = message
                self.error_code = 429
                self.details = details or {}

        exc = MockRateLimitError()
        assert exc.message == "請求過於頻繁"
        assert exc.error_code == 429

    def test_business_logic_error(self):
        """測試業務邏輯錯誤"""

        # 模擬 BusinessLogicError
        class MockBusinessLogicError(Exception):
            def __init__(self, message: str = "業務邏輯錯誤", details: dict = None):
                self.message = message
                self.error_code = 400
                self.details = details or {}

        exc = MockBusinessLogicError("餘額不足")
        assert exc.message == "餘額不足"
        assert exc.error_code == 400

    def test_external_service_error(self):
        """測試外部服務錯誤"""

        # 模擬 ExternalServiceError
        class MockExternalServiceError(Exception):
            def __init__(self, message: str = "外部服務錯誤", details: dict = None):
                self.message = message
                self.error_code = 502
                self.details = details or {}

        exc = MockExternalServiceError("第三方 API 不可用")
        assert exc.message == "第三方 API 不可用"
        assert exc.error_code == 502

    def test_database_error(self):
        """測試資料庫錯誤"""

        # 模擬 DatabaseError
        class MockDatabaseError(Exception):
            def __init__(self, message: str = "資料庫操作失敗", details: dict = None):
                self.message = message
                self.error_code = 500
                self.details = details or {}

        exc = MockDatabaseError("連接超時")
        assert exc.message == "連接超時"
        assert exc.error_code == 500

    def test_retryable_error(self):
        """測試可重試錯誤"""

        # 模擬 RetryableError
        class MockRetryableError(Exception):
            def __init__(
                self,
                message: str = "操作失敗，請重試",
                retry_after: int = 60,
                details: dict = None,
            ):
                self.message = message
                self.error_code = 503
                self.retry_after = retry_after
                self.details = details or {}

        exc = MockRetryableError(retry_after=30)
        assert exc.message == "操作失敗，請重試"
        assert exc.error_code == 503
        assert exc.retry_after == 30

    def test_maintenance_error(self):
        """測試維護模式錯誤"""

        # 模擬 MaintenanceError
        class MockMaintenanceError(Exception):
            def __init__(
                self, message: str = "系統維護中，請稍後再試", details: dict = None
            ):
                self.message = message
                self.error_code = 503
                self.details = details or {}

        exc = MockMaintenanceError()
        assert exc.message == "系統維護中，請稍後再試"
        assert exc.error_code == 503

    def test_exception_logger(self):
        """測試異常日誌記錄器"""

        # 模擬 ExceptionLogger
        class MockExceptionLogger:
            @staticmethod
            def log_exception(exc, request, user_id=None, additional_context=None):
                context = {
                    "exception_type": type(exc).__name__,
                    "exception_message": str(exc),
                    "path": request.url.path if hasattr(request, "url") else "/test",
                    "method": request.method if hasattr(request, "method") else "GET",
                    "user_id": user_id,
                    "timestamp": datetime.now().isoformat(),
                }
                if additional_context:
                    context.update(additional_context)
                return context

        # 測試日誌記錄
        mock_request = Mock()
        mock_request.url.path = "/api/v1/test"
        mock_request.method = "POST"

        exc = Exception("測試異常")
        logger = MockExceptionLogger()
        context = logger.log_exception(exc, mock_request, "user_123", {"extra": "data"})

        assert context["exception_type"] == "Exception"
        assert context["exception_message"] == "測試異常"
        assert context["path"] == "/api/v1/test"
        assert context["method"] == "POST"
        assert context["user_id"] == "user_123"
        assert context["extra"] == "data"

    def test_error_tracker(self):
        """測試錯誤追蹤器"""

        # 模擬 ErrorTracker
        class MockErrorTracker:
            def __init__(self):
                self.error_counts = {}
                self.error_details = []

            def track_error(self, error_type, error_message, endpoint, user_id=None):
                error_key = f"{error_type}:{endpoint}"
                self.error_counts[error_key] = self.error_counts.get(error_key, 0) + 1

                self.error_details.append(
                    {
                        "error_type": error_type,
                        "error_message": error_message,
                        "endpoint": endpoint,
                        "user_id": user_id,
                        "timestamp": datetime.now(),
                        "count": self.error_counts[error_key],
                    }
                )

            def get_error_statistics(self):
                total_errors = sum(self.error_counts.values())
                return {
                    "total_errors": total_errors,
                    "error_counts": self.error_counts,
                    "recent_errors": self.error_details[-10:],
                }

        # 測試錯誤追蹤
        tracker = MockErrorTracker()
        tracker.track_error(
            "ValidationError", "欄位驗證失敗", "/api/v1/users", "user_123"
        )
        tracker.track_error(
            "ValidationError", "欄位驗證失敗", "/api/v1/users", "user_456"
        )
        tracker.track_error(
            "AuthenticationError", "認證失敗", "/api/v1/auth", "user_789"
        )

        stats = tracker.get_error_statistics()
        assert stats["total_errors"] == 3
        assert "ValidationError:/api/v1/users" in stats["error_counts"]
        assert stats["error_counts"]["ValidationError:/api/v1/users"] == 2
        assert len(stats["recent_errors"]) == 3

    def test_database_error_decorator(self):
        """測試資料庫錯誤處理裝飾器"""

        # 模擬資料庫錯誤處理裝飾器
        def mock_handle_database_error(func):
            def wrapper(*args, **kwargs):
                try:
                    return func(*args, **kwargs)
                except Exception as e:
                    raise Exception(f"資料庫操作失敗: {str(e)}") from e

            return wrapper

        @mock_handle_database_error
        def database_operation():
            raise Exception("連接失敗")

        # 測試裝飾器功能
        with pytest.raises(Exception) as exc_info:
            database_operation()

        assert "資料庫操作失敗" in str(exc_info.value)
        assert exc_info.value.__cause__ is not None

    def test_external_service_error_decorator(self):
        """測試外部服務錯誤處理裝飾器"""

        # 模擬外部服務錯誤處理裝飾器
        def mock_handle_external_service_error(service_name):
            def decorator(func):
                def wrapper(*args, **kwargs):
                    try:
                        return func(*args, **kwargs)
                    except Exception as e:
                        raise Exception(f"{service_name} 服務不可用: {str(e)}") from e

                return wrapper

            return decorator

        @mock_handle_external_service_error("支付服務")
        def call_payment_service():
            raise Exception("網路超時")

        # 測試裝飾器功能
        with pytest.raises(Exception) as exc_info:
            call_payment_service()

        assert "支付服務 服務不可用" in str(exc_info.value)
        assert exc_info.value.__cause__ is not None

    def test_exception_handler_setup(self):
        """測試異常處理器設定"""
        # 模擬異常處理器設定
        mock_app = Mock()
        handlers = []

        def mock_exception_handler(exception_type):
            def decorator(handler_func):
                handlers.append((exception_type, handler_func))
                return handler_func

            return decorator

        mock_app.exception_handler = mock_exception_handler

        # 模擬設定異常處理器
        @mock_app.exception_handler(Exception)
        async def general_exception_handler(request, exc):
            return {"error": str(exc)}

        @mock_app.exception_handler(ValueError)
        async def validation_exception_handler(request, exc):
            return {"validation_error": str(exc)}

        # 驗證處理器註冊
        assert len(handlers) == 2
        assert handlers[0][0] == Exception
        assert handlers[1][0] == ValueError

    def teardown_method(self):
        """測試後清理"""
        self.test_timestamp = None


if __name__ == "__main__":
    pytest.main([__file__, "-v"])
